Workbook

Sheet Deals Won (Live update)
C1: WorkDrive Presales - Deals Won (Live Dashboard) - 2026
C3: Auto-calculated from all 12 monthly tabs. Mark any row "Deal Won" anywhere including later-month conversions and every figure & chart updates automatically.
B5: TOTAL DEALS WON | E5: TOTAL DEALS LOST | H5: IN PROGRESS | J5: WIN RATE
B6: =COUNTIF('January'!$P$2:$P$2000,"Deal Won")+COUNTIF('February'!$P$2:$P$2000,"Deal Won")+COUNTIF('March'!$P$2:$P$2000,"Deal Won")+COUNTIF('April'!$P$2:$P$2000,"Deal Won")+COUNTIF('May'!$P$2:$P$2000,"Deal Won")+COUNTIF('June'!$P$2:$P$2002,"Deal Won")+COUNTIF('July'!$P$2:$P$2000,"Deal Won")+COUNTIF('August'!$P$2:$P$2000,"Deal Won")+COUNTIF('September'!$P$2:$P$2000,"Deal Won")+COUNTIF('October'!$P$2:$P$2000,"Deal Won")+COUNTIF('November'!$P$2:$P$2000,"Deal Won")+COUNTIF('December'!$P$2:$P$2000,"Deal Won") -> 129 | E6: =COUNTIF('January'!$P$2:$P$2000,"Deal Lost")+COUNTIF('February'!$P$2:$P$2000,"Deal Lost")+COUNTIF('March'!$P$2:$P$2000,"Deal Lost")+COUNTIF('April'!$P$2:$P$2000,"Deal Lost")+COUNTIF('May'!$P$2:$P$2000,"Deal Lost")+COUNTIF('June'!$P$2:$P$2002,"Deal Lost")+COUNTIF('July'!$P$2:$P$2000,"Deal Lost")+COUNTIF('August'!$P$2:$P$2000,"Deal Lost")+COUNTIF('September'!$P$2:$P$2000,"Deal Lost")+COUNTIF('October'!$P$2:$P$2000,"Deal Lost")+COUNTIF('November'!$P$2:$P$2000,"Deal Lost")+COUNTIF('December'!$P$2:$P$2000,"Deal Lost") -> 238 | H6: =COUNTIF('January'!$P$2:$P$2000,"In Progress")+COUNTIF('February'!$P$2:$P$2000,"In Progress")+COUNTIF('March'!$P$2:$P$2000,"In Progress")+COUNTIF('April'!$P$2:$P$2000,"In Progress")+COUNTIF('May'!$P$2:$P$2000,"In Progress")+COUNTIF('June'!$P$2:$P$2002,"In Progress")+COUNTIF('July'!$P$2:$P$2000,"In Progress")+COUNTIF('August'!$P$2:$P$2000,"In Progress")+COUNTIF('September'!$P$2:$P$2000,"In Progress")+COUNTIF('October'!$P$2:$P$2000,"In Progress")+COUNTIF('November'!$P$2:$P$2000,"In Progress")+COUNTIF('December'!$P$2:$P$2000,"In Progress") -> 87 | J6: =IF(B6+E6=0,0,B6/(B6+E6)) -> 0.35149864
A9: DEALS WON BY MONTH (live count per tab)
A10: Month | B10: Demos Logged | C10: Deal Won | D10: Deal Lost | E10: In Progress | F10: Win %
A11: January | B11: =COUNTIF('January'!$P$2:$P$2000,"Deal Won")+COUNTIF('January'!$P$2:$P$2000,"Deal Lost")+COUNTIF('January'!$P$2:$P$2000,"In Progress")+COUNTIF('January'!$P$2:$P$2000,"Existing customer")+COUNTIF('January'!$P$2:$P$2000,"No Scope for WD")+COUNTIF('January'!$P$2:$P$2000,"Free user")+COUNTIF('January'!$P$2:$P$2000,"Partner") -> 99 | C11: =COUNTIF('January'!$P$2:$P$2000,"Deal Won") -> 31 | D11: =COUNTIF('January'!$P$2:$P$2000,"Deal Lost") -> 53 | E11: =COUNTIF('January'!$P$2:$P$2000,"In Progress") -> 0 | F11: =IF(C11+D11=0,0,C11/(C11+D11)) -> 0.36904762 | Z11: Demos Logged | AA11: Month | AB11: New-Prospect Demos | AC11: Non-prospects
A12: February | B12: =COUNTIF('February'!$P$2:$P$2000,"Deal Won")+COUNTIF('February'!$P$2:$P$2000,"Deal Lost")+COUNTIF('February'!$P$2:$P$2000,"In Progress")+COUNTIF('February'!$P$2:$P$2000,"Existing customer")+COUNTIF('February'!$P$2:$P$2000,"No Scope for WD")+COUNTIF('February'!$P$2:$P$2000,"Free user")+COUNTIF('February'!$P$2:$P$2000,"Partner") -> 98 | C12: =COUNTIF('February'!$P$2:$P$2000,"Deal Won") -> 25 | D12: =COUNTIF('February'!$P$2:$P$2000,"Deal Lost") -> 57 | E12: =COUNTIF('February'!$P$2:$P$2000,"In Progress") -> 3 | F12: =IF(C12+D12=0,0,C12/(C12+D12)) -> 0.30487805 | Z12: =COUNTIF('January'!$P$2:$P$2000,"Deal Won")+COUNTIF('January'!$P$2:$P$2000,"Deal Lost")+COUNTIF('January'!$P$2:$P$2000,"In Progress")+COUNTIF('January'!$P$2:$P$2000,"Existing customer")+COUNTIF('January'!$P$2:$P$2000,"No Scope for WD")+COUNTIF('January'!$P$2:$P$2000,"Free user")+COUNTIF('January'!$P$2:$P$2000,"Partner") -> 99 | AA12: January | AB12: =COUNTIFS('January'!$P$2:$P$2000,"Deal Won",'January'!$N$2:$N$2000,"New Prospect")+COUNTIFS('January'!$P$2:$P$2000,"Deal Lost",'January'!$N$2:$N$2000,"New Prospect")+COUNTIFS('January'!$P$2:$P$2000,"In Progress",'January'!$N$2:$N$2000,"New Prospect") -> 79 | AC12: =Z12-AB12 -> 20
A13: March | B13: =COUNTIF('March'!$P$2:$P$2000,"Deal Won")+COUNTIF('March'!$P$2:$P$2000,"Deal Lost")+COUNTIF('March'!$P$2:$P$2000,"In Progress")+COUNTIF('March'!$P$2:$P$2000,"Existing customer")+COUNTIF('March'!$P$2:$P$2000,"No Scope for WD")+COUNTIF('March'!$P$2:$P$2000,"Free user")+COUNTIF('March'!$P$2:$P$2000,"Partner") -> 117 | C13: =COUNTIF('March'!$P$2:$P$2000,"Deal Won") -> 28 | D13: =COUNTIF('March'!$P$2:$P$2000,"Deal Lost") -> 48 | E13: =COUNTIF('March'!$P$2:$P$2000,"In Progress") -> 10 | F13: =IF(C13+D13=0,0,C13/(C13+D13)) -> 0.36842105 | Z13: =COUNTIF('February'!$P$2:$P$2000,"Deal Won")+COUNTIF('February'!$P$2:$P$2000,"Deal Lost")+COUNTIF('February'!$P$2:$P$2000,"In Progress")+COUNTIF('February'!$P$2:$P$2000,"Existing customer")+COUNTIF('February'!$P$2:$P$2000,"No Scope for WD")+COUNTIF('February'!$P$2:$P$2000,"Free user")+COUNTIF('February'!$P$2:$P$2000,"Partner") -> 98 | AA13: February | AB13: =COUNTIFS('February'!$P$2:$P$2000,"Deal Won",'February'!$N$2:$N$2000,"New Prospect")+COUNTIFS('February'!$P$2:$P$2000,"Deal Lost",'February'!$N$2:$N$2000,"New Prospect")+COUNTIFS('February'!$P$2:$P$2000,"In Progress",'February'!$N$2:$N$2000,"New Prospect") -> 71 | AC13: =Z13-AB13 -> 27
A14: April | B14: =COUNTIF('April'!$P$2:$P$2000,"Deal Won")+COUNTIF('April'!$P$2:$P$2000,"Deal Lost")+COUNTIF('April'!$P$2:$P$2000,"In Progress")+COUNTIF('April'!$P$2:$P$2000,"Existing customer")+COUNTIF('April'!$P$2:$P$2000,"No Scope for WD")+COUNTIF('April'!$P$2:$P$2000,"Free user")+COUNTIF('April'!$P$2:$P$2000,"Partner") -> 105 | C14: =COUNTIF('April'!$P$2:$P$2000,"Deal Won") -> 28 | D14: =COUNTIF('April'!$P$2:$P$2000,"Deal Lost") -> 38 | E14: =COUNTIF('April'!$P$2:$P$2000,"In Progress") -> 13 | F14: =IF(C14+D14=0,0,C14/(C14+D14)) -> 0.42424242 | Z14: =COUNTIF('March'!$P$2:$P$2000,"Deal Won")+COUNTIF('March'!$P$2:$P$2000,"Deal Lost")+COUNTIF('March'!$P$2:$P$2000,"In Progress")+COUNTIF('March'!$P$2:$P$2000,"Existing customer")+COUNTIF('March'!$P$2:$P$2000,"No Scope for WD")+COUNTIF('March'!$P$2:$P$2000,"Free user")+COUNTIF('March'!$P$2:$P$2000,"Partner") -> 117 | AA14: March | AB14: =COUNTIFS('March'!$P$2:$P$2000,"Deal Won",'March'!$N$2:$N$2000,"New Prospect")+COUNTIFS('March'!$P$2:$P$2000,"Deal Lost",'March'!$N$2:$N$2000,"New Prospect")+COUNTIFS('March'!$P$2:$P$2000,"In Progress",'March'!$N$2:$N$2000,"New Prospect") -> 74 | AC14: =Z14-AB14 -> 43
A15: May | B15: =COUNTIF('May'!$P$2:$P$2000,"Deal Won")+COUNTIF('May'!$P$2:$P$2000,"Deal Lost")+COUNTIF('May'!$P$2:$P$2000,"In Progress")+COUNTIF('May'!$P$2:$P$2000,"Existing customer")+COUNTIF('May'!$P$2:$P$2000,"No Scope for WD")+COUNTIF('May'!$P$2:$P$2000,"Free user")+COUNTIF('May'!$P$2:$P$2000,"Partner") -> 97 | C15: =COUNTIF('May'!$P$2:$P$2000,"Deal Won") -> 15 | D15: =COUNTIF('May'!$P$2:$P$2000,"Deal Lost") -> 41 | E15: =COUNTIF('May'!$P$2:$P$2000,"In Progress") -> 19 | F15: =IF(C15+D15=0,0,C15/(C15+D15)) -> 0.26785714 | Z15: =COUNTIF('April'!$P$2:$P$2000,"Deal Won")+COUNTIF('April'!$P$2:$P$2000,"Deal Lost")+COUNTIF('April'!$P$2:$P$2000,"In Progress")+COUNTIF('April'!$P$2:$P$2000,"Existing customer")+COUNTIF('April'!$P$2:$P$2000,"No Scope for WD")+COUNTIF('April'!$P$2:$P$2000,"Free user")+COUNTIF('April'!$P$2:$P$2000,"Partner") -> 105 | AA15: April | AB15: =COUNTIFS('April'!$P$2:$P$2000,"Deal Won",'April'!$N$2:$N$2000,"New Prospect")+COUNTIFS('April'!$P$2:$P$2000,"Deal Lost",'April'!$N$2:$N$2000,"New Prospect")+COUNTIFS('April'!$P$2:$P$2000,"In Progress",'April'!$N$2:$N$2000,"New Prospect") -> 61 | AC15: =Z15-AB15 -> 44
A16: June | B16: =COUNTIF('June'!$P$2:$P$2002,"Deal Won")+COUNTIF('June'!$P$2:$P$2002,"Deal Lost")+COUNTIF('June'!$P$2:$P$2002,"In Progress")+COUNTIF('June'!$P$2:$P$2002,"Existing customer")+COUNTIF('June'!$P$2:$P$2002,"No Scope for WD")+COUNTIF('June'!$P$2:$P$2002,"Free user")+COUNTIF('June'!$P$2:$P$2002,"Partner") -> 54 | C16: =COUNTIF('June'!$P$2:$P$2002,"Deal Won") -> 2 | D16: =COUNTIF('June'!$P$2:$P$2002,"Deal Lost") -> 1 | E16: =COUNTIF('June'!$P$2:$P$2002,"In Progress") -> 42 | F16: =IF(C16+D16=0,0,C16/(C16+D16)) -> 0.66666667 | Z16: =COUNTIF('May'!$P$2:$P$2000,"Deal Won")+COUNTIF('May'!$P$2:$P$2000,"Deal Lost")+COUNTIF('May'!$P$2:$P$2000,"In Progress")+COUNTIF('May'!$P$2:$P$2000,"Existing customer")+COUNTIF('May'!$P$2:$P$2000,"No Scope for WD")+COUNTIF('May'!$P$2:$P$2000,"Free user")+COUNTIF('May'!$P$2:$P$2000,"Partner") -> 97 | AA16: May | AB16: =COUNTIFS('May'!$P$2:$P$2000,"Deal Won",'May'!$N$2:$N$2000,"New Prospect")+COUNTIFS('May'!$P$2:$P$2000,"Deal Lost",'May'!$N$2:$N$2000,"New Prospect")+COUNTIFS('May'!$P$2:$P$2000,"In Progress",'May'!$N$2:$N$2000,"New Prospect") -> 63 | AC16: =Z16-AB16 -> 34
A17: July | B17: =COUNTIF('July'!$P$2:$P$2000,"Deal Won")+COUNTIF('July'!$P$2:$P$2000,"Deal Lost")+COUNTIF('July'!$P$2:$P$2000,"In Progress")+COUNTIF('July'!$P$2:$P$2000,"Existing customer")+COUNTIF('July'!$P$2:$P$2000,"No Scope for WD")+COUNTIF('July'!$P$2:$P$2000,"Free user")+COUNTIF('July'!$P$2:$P$2000,"Partner") -> 0 | C17: =COUNTIF('July'!$P$2:$P$2000,"Deal Won") -> 0 | D17: =COUNTIF('July'!$P$2:$P$2000,"Deal Lost") -> 0 | E17: =COUNTIF('July'!$P$2:$P$2000,"In Progress") -> 0 | F17: =IF(C17+D17=0,0,C17/(C17+D17)) -> 0 | Z17: =COUNTIF('June'!$P$2:$P$2002,"Deal Won")+COUNTIF('June'!$P$2:$P$2002,"Deal Lost")+COUNTIF('June'!$P$2:$P$2002,"In Progress")+COUNTIF('June'!$P$2:$P$2002,"Existing customer")+COUNTIF('June'!$P$2:$P$2002,"No Scope for WD")+COUNTIF('June'!$P$2:$P$2002,"Free user")+COUNTIF('June'!$P$2:$P$2002,"Partner") -> 54 | AA17: June | AB17: =COUNTIFS('June'!$P$2:$P$2002,"Deal Won",'June'!$N$2:$N$2002,"New Prospect")+COUNTIFS('June'!$P$2:$P$2002,"Deal Lost",'June'!$N$2:$N$2002,"New Prospect")+COUNTIFS('June'!$P$2:$P$2002,"In Progress",'June'!$N$2:$N$2002,"New Prospect") -> 38 | AC17: =Z17-AB17 -> 16
A18: August | B18: =COUNTIF('August'!$P$2:$P$2000,"Deal Won")+COUNTIF('August'!$P$2:$P$2000,"Deal Lost")+COUNTIF('August'!$P$2:$P$2000,"In Progress")+COUNTIF('August'!$P$2:$P$2000,"Existing customer")+COUNTIF('August'!$P$2:$P$2000,"No Scope for WD")+COUNTIF('August'!$P$2:$P$2000,"Free user")+COUNTIF('August'!$P$2:$P$2000,"Partner") -> 0 | C18: =COUNTIF('August'!$P$2:$P$2000,"Deal Won") -> 0 | D18: =COUNTIF('August'!$P$2:$P$2000,"Deal Lost") -> 0 | E18: =COUNTIF('August'!$P$2:$P$2000,"In Progress") -> 0 | F18: =IF(C18+D18=0,0,C18/(C18+D18)) -> 0 | Z18: =COUNTIF('July'!$P$2:$P$2000,"Deal Won")+COUNTIF('July'!$P$2:$P$2000,"Deal Lost")+COUNTIF('July'!$P$2:$P$2000,"In Progress")+COUNTIF('July'!$P$2:$P$2000,"Existing customer")+COUNTIF('July'!$P$2:$P$2000,"No Scope for WD")+COUNTIF('July'!$P$2:$P$2000,"Free user")+COUNTIF('July'!$P$2:$P$2000,"Partner") -> 0 | AA18: July | AB18: =COUNTIFS('July'!$P$2:$P$2000,"Deal Won",'July'!$N$2:$N$2000,"New Prospect")+COUNTIFS('July'!$P$2:$P$2000,"Deal Lost",'July'!$N$2:$N$2000,"New Prospect")+COUNTIFS('July'!$P$2:$P$2000,"In Progress",'July'!$N$2:$N$2000,"New Prospect") -> 0 | AC18: =Z18-AB18 -> 0
A19: September | B19: =COUNTIF('September'!$P$2:$P$2000,"Deal Won")+COUNTIF('September'!$P$2:$P$2000,"Deal Lost")+COUNTIF('September'!$P$2:$P$2000,"In Progress")+COUNTIF('September'!$P$2:$P$2000,"Existing customer")+COUNTIF('September'!$P$2:$P$2000,"No Scope for WD")+COUNTIF('September'!$P$2:$P$2000,"Free user")+COUNTIF('September'!$P$2:$P$2000,"Partner") -> 0 | C19: =COUNTIF('September'!$P$2:$P$2000,"Deal Won") -> 0 | D19: =COUNTIF('September'!$P$2:$P$2000,"Deal Lost") -> 0 | E19: =COUNTIF('September'!$P$2:$P$2000,"In Progress") -> 0 | F19: =IF(C19+D19=0,0,C19/(C19+D19)) -> 0 | Z19: =COUNTIF('August'!$P$2:$P$2000,"Deal Won")+COUNTIF('August'!$P$2:$P$2000,"Deal Lost")+COUNTIF('August'!$P$2:$P$2000,"In Progress")+COUNTIF('August'!$P$2:$P$2000,"Existing customer")+COUNTIF('August'!$P$2:$P$2000,"No Scope for WD")+COUNTIF('August'!$P$2:$P$2000,"Free user")+COUNTIF('August'!$P$2:$P$2000,"Partner") -> 0 | AA19: August | AB19: =COUNTIFS('August'!$P$2:$P$2000,"Deal Won",'August'!$N$2:$N$2000,"New Prospect")+COUNTIFS('August'!$P$2:$P$2000,"Deal Lost",'August'!$N$2:$N$2000,"New Prospect")+COUNTIFS('August'!$P$2:$P$2000,"In Progress",'August'!$N$2:$N$2000,"New Prospect") -> 0 | AC19: =Z19-AB19 -> 0
A20: October | B20: =COUNTIF('October'!$P$2:$P$2000,"Deal Won")+COUNTIF('October'!$P$2:$P$2000,"Deal Lost")+COUNTIF('October'!$P$2:$P$2000,"In Progress")+COUNTIF('October'!$P$2:$P$2000,"Existing customer")+COUNTIF('October'!$P$2:$P$2000,"No Scope for WD")+COUNTIF('October'!$P$2:$P$2000,"Free user")+COUNTIF('October'!$P$2:$P$2000,"Partner") -> 0 | C20: =COUNTIF('October'!$P$2:$P$2000,"Deal Won") -> 0 | D20: =COUNTIF('October'!$P$2:$P$2000,"Deal Lost") -> 0 | E20: =COUNTIF('October'!$P$2:$P$2000,"In Progress") -> 0 | F20: =IF(C20+D20=0,0,C20/(C20+D20)) -> 0 | Z20: =COUNTIF('September'!$P$2:$P$2000,"Deal Won")+COUNTIF('September'!$P$2:$P$2000,"Deal Lost")+COUNTIF('September'!$P$2:$P$2000,"In Progress")+COUNTIF('September'!$P$2:$P$2000,"Existing customer")+COUNTIF('September'!$P$2:$P$2000,"No Scope for WD")+COUNTIF('September'!$P$2:$P$2000,"Free user")+COUNTIF('September'!$P$2:$P$2000,"Partner") -> 0 | AA20: September | AB20: =COUNTIFS('September'!$P$2:$P$2000,"Deal Won",'September'!$N$2:$N$2000,"New Prospect")+COUNTIFS('September'!$P$2:$P$2000,"Deal Lost",'September'!$N$2:$N$2000,"New Prospect")+COUNTIFS('September'!$P$2:$P$2000,"In Progress",'September'!$N$2:$N$2000,"New Prospect") -> 0 | AC20: =Z20-AB20 -> 0
A21: November | B21: =COUNTIF('November'!$P$2:$P$2000,"Deal Won")+COUNTIF('November'!$P$2:$P$2000,"Deal Lost")+COUNTIF('November'!$P$2:$P$2000,"In Progress")+COUNTIF('November'!$P$2:$P$2000,"Existing customer")+COUNTIF('November'!$P$2:$P$2000,"No Scope for WD")+COUNTIF('November'!$P$2:$P$2000,"Free user")+COUNTIF('November'!$P$2:$P$2000,"Partner") -> 0 | C21: =COUNTIF('November'!$P$2:$P$2000,"Deal Won") -> 0 | D21: =COUNTIF('November'!$P$2:$P$2000,"Deal Lost") -> 0 | E21: =COUNTIF('November'!$P$2:$P$2000,"In Progress") -> 0 | F21: =IF(C21+D21=0,0,C21/(C21+D21)) -> 0 | Z21: =COUNTIF('October'!$P$2:$P$2000,"Deal Won")+COUNTIF('October'!$P$2:$P$2000,"Deal Lost")+COUNTIF('October'!$P$2:$P$2000,"In Progress")+COUNTIF('October'!$P$2:$P$2000,"Existing customer")+COUNTIF('October'!$P$2:$P$2000,"No Scope for WD")+COUNTIF('October'!$P$2:$P$2000,"Free user")+COUNTIF('October'!$P$2:$P$2000,"Partner") -> 0 | AA21: October | AB21: =COUNTIFS('October'!$P$2:$P$2000,"Deal Won",'October'!$N$2:$N$2000,"New Prospect")+COUNTIFS('October'!$P$2:$P$2000,"Deal Lost",'October'!$N$2:$N$2000,"New Prospect")+COUNTIFS('October'!$P$2:$P$2000,"In Progress",'October'!$N$2:$N$2000,"New Prospect") -> 0 | AC21: =Z21-AB21 -> 0
A22: December | B22: =COUNTIF('December'!$P$2:$P$2000,"Deal Won")+COUNTIF('December'!$P$2:$P$2000,"Deal Lost")+COUNTIF('December'!$P$2:$P$2000,"In Progress")+COUNTIF('December'!$P$2:$P$2000,"Existing customer")+COUNTIF('December'!$P$2:$P$2000,"No Scope for WD")+COUNTIF('December'!$P$2:$P$2000,"Free user")+COUNTIF('December'!$P$2:$P$2000,"Partner") -> 0 | C22: =COUNTIF('December'!$P$2:$P$2000,"Deal Won") -> 0 | D22: =COUNTIF('December'!$P$2:$P$2000,"Deal Lost") -> 0 | E22: =COUNTIF('December'!$P$2:$P$2000,"In Progress") -> 0 | F22: =IF(C22+D22=0,0,C22/(C22+D22)) -> 0 | Z22: =COUNTIF('November'!$P$2:$P$2000,"Deal Won")+COUNTIF('November'!$P$2:$P$2000,"Deal Lost")+COUNTIF('November'!$P$2:$P$2000,"In Progress")+COUNTIF('November'!$P$2:$P$2000,"Existing customer")+COUNTIF('November'!$P$2:$P$2000,"No Scope for WD")+COUNTIF('November'!$P$2:$P$2000,"Free user")+COUNTIF('November'!$P$2:$P$2000,"Partner") -> 0 | AA22: November | AB22: =COUNTIFS('November'!$P$2:$P$2000,"Deal Won",'November'!$N$2:$N$2000,"New Prospect")+COUNTIFS('November'!$P$2:$P$2000,"Deal Lost",'November'!$N$2:$N$2000,"New Prospect")+COUNTIFS('November'!$P$2:$P$2000,"In Progress",'November'!$N$2:$N$2000,"New Prospect") -> 0 | AC22: =Z22-AB22 -> 0
A23: TOTAL | B23: =SUM(B11:B22) -> 570 | C23: =SUM(C11:C22) -> 129 | D23: =SUM(D11:D22) -> 238 | E23: =SUM(E11:E22) -> 87 | F23: =IF(C23+D23=0,0,C23/(C23+D23)) -> 0.35149864 | Z23: =COUNTIF('December'!$P$2:$P$2000,"Deal Won")+COUNTIF('December'!$P$2:$P$2000,"Deal Lost")+COUNTIF('December'!$P$2:$P$2000,"In Progress")+COUNTIF('December'!$P$2:$P$2000,"Existing customer")+COUNTIF('December'!$P$2:$P$2000,"No Scope for WD")+COUNTIF('December'!$P$2:$P$2000,"Free user")+COUNTIF('December'!$P$2:$P$2000,"Partner") -> 0 | AA23: December | AB23: =COUNTIFS('December'!$P$2:$P$2000,"Deal Won",'December'!$N$2:$N$2000,"New Prospect")+COUNTIFS('December'!$P$2:$P$2000,"Deal Lost",'December'!$N$2:$N$2000,"New Prospect")+COUNTIFS('December'!$P$2:$P$2000,"In Progress",'December'!$N$2:$N$2000,"New Prospect") -> 0 | AC23: =Z23-AB23 -> 0
A26: NEW-PROSPECT CONVERSION
A27: Month | B27: New-Prospect Demos | C27: Deal Won | D27: Deal Lost | E27: In Progress | F27: Conversion %
A28: January | B28: =COUNTIFS('January'!$P$2:$P$2000,"Deal Won",'January'!$N$2:$N$2000,"New Prospect")+COUNTIFS('January'!$P$2:$P$2000,"Deal Lost",'January'!$N$2:$N$2000,"New Prospect")+COUNTIFS('January'!$P$2:$P$2000,"In Progress",'January'!$N$2:$N$2000,"New Prospect") -> 79 | C28: =COUNTIFS('January'!$P$2:$P$2000,"Deal Won",'January'!$N$2:$N$2000,"New Prospect") -> 28 | D28: =COUNTIFS('January'!$P$2:$P$2000,"Deal Lost",'January'!$N$2:$N$2000,"New Prospect") -> 51 | E28: =COUNTIFS('January'!$P$2:$P$2000,"In Progress",'January'!$N$2:$N$2000,"New Prospect") -> 0 | F28: =IF(B28=0,0,C28/B28) -> 0.35443038
A29: February | B29: =COUNTIFS('February'!$P$2:$P$2000,"Deal Won",'February'!$N$2:$N$2000,"New Prospect")+COUNTIFS('February'!$P$2:$P$2000,"Deal Lost",'February'!$N$2:$N$2000,"New Prospect")+COUNTIFS('February'!$P$2:$P$2000,"In Progress",'February'!$N$2:$N$2000,"New Prospect") -> 71 | C29: =COUNTIFS('February'!$P$2:$P$2000,"Deal Won",'February'!$N$2:$N$2000,"New Prospect") -> 21 | D29: =COUNTIFS('February'!$P$2:$P$2000,"Deal Lost",'February'!$N$2:$N$2000,"New Prospect") -> 48 | E29: =COUNTIFS('February'!$P$2:$P$2000,"In Progress",'February'!$N$2:$N$2000,"New Prospect") -> 2 | F29: =IF(B29=0,0,C29/B29) -> 0.29577465
A30: March | B30: =COUNTIFS('March'!$P$2:$P$2000,"Deal Won",'March'!$N$2:$N$2000,"New Prospect")+COUNTIFS('March'!$P$2:$P$2000,"Deal Lost",'March'!$N$2:$N$2000,"New Prospect")+COUNTIFS('March'!$P$2:$P$2000,"In Progress",'March'!$N$2:$N$2000,"New Prospect") -> 74 | C30: =COUNTIFS('March'!$P$2:$P$2000,"Deal Won",'March'!$N$2:$N$2000,"New Prospect") -> 25 | D30: =COUNTIFS('March'!$P$2:$P$2000,"Deal Lost",'March'!$N$2:$N$2000,"New Prospect") -> 43 | E30: =COUNTIFS('March'!$P$2:$P$2000,"In Progress",'March'!$N$2:$N$2000,"New Prospect") -> 6 | F30: =IF(B30=0,0,C30/B30) -> 0.33783784
A31: April | B31: =COUNTIFS('April'!$P$2:$P$2000,"Deal Won",'April'!$N$2:$N$2000,"New Prospect")+COUNTIFS('April'!$P$2:$P$2000,"Deal Lost",'April'!$N$2:$N$2000,"New Prospect")+COUNTIFS('April'!$P$2:$P$2000,"In Progress",'April'!$N$2:$N$2000,"New Prospect") -> 61 | C31: =COUNTIFS('April'!$P$2:$P$2000,"Deal Won",'April'!$N$2:$N$2000,"New Prospect") -> 21 | D31: =COUNTIFS('April'!$P$2:$P$2000,"Deal Lost",'April'!$N$2:$N$2000,"New Prospect") -> 32 | E31: =COUNTIFS('April'!$P$2:$P$2000,"In Progress",'April'!$N$2:$N$2000,"New Prospect") -> 8 | F31: =IF(B31=0,0,C31/B31) -> 0.3442623
A32: May | B32: =COUNTIFS('May'!$P$2:$P$2000,"Deal Won",'May'!$N$2:$N$2000,"New Prospect")+COUNTIFS('May'!$P$2:$P$2000,"Deal Lost",'May'!$N$2:$N$2000,"New Prospect")+COUNTIFS('May'!$P$2:$P$2000,"In Progress",'May'!$N$2:$N$2000,"New Prospect") -> 63 | C32: =COUNTIFS('May'!$P$2:$P$2000,"Deal Won",'May'!$N$2:$N$2000,"New Prospect") -> 10 | D32: =COUNTIFS('May'!$P$2:$P$2000,"Deal Lost",'May'!$N$2:$N$2000,"New Prospect") -> 37 | E32: =COUNTIFS('May'!$P$2:$P$2000,"In Progress",'May'!$N$2:$N$2000,"New Prospect") -> 16 | F32: =IF(B32=0,0,C32/B32) -> 0.15873016
A33: June | B33: =COUNTIFS('June'!$P$2:$P$2002,"Deal Won",'June'!$N$2:$N$2002,"New Prospect")+COUNTIFS('June'!$P$2:$P$2002,"Deal Lost",'June'!$N$2:$N$2002,"New Prospect")+COUNTIFS('June'!$P$2:$P$2002,"In Progress",'June'!$N$2:$N$2002,"New Prospect") -> 38 | C33: =COUNTIFS('June'!$P$2:$P$2002,"Deal Won",'June'!$N$2:$N$2002,"New Prospect") -> 2 | D33: =COUNTIFS('June'!$P$2:$P$2002,"Deal Lost",'June'!$N$2:$N$2002,"New Prospect") -> 0 | E33: =COUNTIFS('June'!$P$2:$P$2002,"In Progress",'June'!$N$2:$N$2002,"New Prospect") -> 36 | F33: =IF(B33=0,0,C33/B33) -> 0.052631579
A34: July | B34: =COUNTIFS('July'!$P$2:$P$2000,"Deal Won",'July'!$N$2:$N$2000,"New Prospect")+COUNTIFS('July'!$P$2:$P$2000,"Deal Lost",'July'!$N$2:$N$2000,"New Prospect")+COUNTIFS('July'!$P$2:$P$2000,"In Progress",'July'!$N$2:$N$2000,"New Prospect") -> 0 | C34: =COUNTIFS('July'!$P$2:$P$2000,"Deal Won",'July'!$N$2:$N$2000,"New Prospect") -> 0 | D34: =COUNTIFS('July'!$P$2:$P$2000,"Deal Lost",'July'!$N$2:$N$2000,"New Prospect") -> 0 | E34: =COUNTIFS('July'!$P$2:$P$2000,"In Progress",'July'!$N$2:$N$2000,"New Prospect") -> 0 | F34: =IF(B34=0,0,C34/B34) -> 0
A35: August | B35: =COUNTIFS('August'!$P$2:$P$2000,"Deal Won",'August'!$N$2:$N$2000,"New Prospect")+COUNTIFS('August'!$P$2:$P$2000,"Deal Lost",'August'!$N$2:$N$2000,"New Prospect")+COUNTIFS('August'!$P$2:$P$2000,"In Progress",'August'!$N$2:$N$2000,"New Prospect") -> 0 | C35: =COUNTIFS('August'!$P$2:$P$2000,"Deal Won",'August'!$N$2:$N$2000,"New Prospect") -> 0 | D35: =COUNTIFS('August'!$P$2:$P$2000,"Deal Lost",'August'!$N$2:$N$2000,"New Prospect") -> 0 | E35: =COUNTIFS('August'!$P$2:$P$2000,"In Progress",'August'!$N$2:$N$2000,"New Prospect") -> 0 | F35: =IF(B35=0,0,C35/B35) -> 0
A36: September | B36: =COUNTIFS('September'!$P$2:$P$2000,"Deal Won",'September'!$N$2:$N$2000,"New Prospect")+COUNTIFS('September'!$P$2:$P$2000,"Deal Lost",'September'!$N$2:$N$2000,"New Prospect")+COUNTIFS('September'!$P$2:$P$2000,"In Progress",'September'!$N$2:$N$2000,"New Prospect") -> 0 | C36: =COUNTIFS('September'!$P$2:$P$2000,"Deal Won",'January'!$N$2:$N$2000,"New Prospect") -> 0 | D36: =COUNTIFS('September'!$P$2:$P$2000,"Deal Lost",'September'!$N$2:$N$2000,"New Prospect") -> 0 | E36: =COUNTIFS('September'!$P$2:$P$2000,"In Progress",'September'!$N$2:$N$2000,"New Prospect") -> 0 | F36: =IF(B36=0,0,C36/B36) -> 0
A37: October | B37: =COUNTIFS('October'!$P$2:$P$2000,"Deal Won",'October'!$N$2:$N$2000,"New Prospect")+COUNTIFS('October'!$P$2:$P$2000,"Deal Lost",'October'!$N$2:$N$2000,"New Prospect")+COUNTIFS('October'!$P$2:$P$2000,"In Progress",'October'!$N$2:$N$2000,"New Prospect") -> 0 | C37: =COUNTIFS('October'!$P$2:$P$2000,"Deal Won",'October'!$N$2:$N$2000,"New Prospect") -> 0 | D37: =COUNTIFS('October'!$P$2:$P$2000,"Deal Lost",'October'!$N$2:$N$2000,"New Prospect") -> 0 | E37: =COUNTIFS('October'!$P$2:$P$2000,"In Progress",'October'!$N$2:$N$2000,"New Prospect") -> 0 | F37: =IF(B37=0,0,C37/B37) -> 0
A38: November | B38: =COUNTIFS('November'!$P$2:$P$2000,"Deal Won",'November'!$N$2:$N$2000,"New Prospect")+COUNTIFS('November'!$P$2:$P$2000,"Deal Lost",'November'!$N$2:$N$2000,"New Prospect")+COUNTIFS('November'!$P$2:$P$2000,"In Progress",'November'!$N$2:$N$2000,"New Prospect") -> 0 | C38: =COUNTIFS('November'!$P$2:$P$2000,"Deal Won",'November'!$N$2:$N$2000,"New Prospect") -> 0 | D38: =COUNTIFS('November'!$P$2:$P$2000,"Deal Lost",'November'!$N$2:$N$2000,"New Prospect") -> 0 | E38: =COUNTIFS('November'!$P$2:$P$2000,"In Progress",'November'!$N$2:$N$2000,"New Prospect") -> 0 | F38: =IF(B38=0,0,C38/B38) -> 0
A39: December | B39: =COUNTIFS('December'!$P$2:$P$2000,"Deal Won",'December'!$N$2:$N$2000,"New Prospect")+COUNTIFS('December'!$P$2:$P$2000,"Deal Lost",'December'!$N$2:$N$2000,"New Prospect")+COUNTIFS('December'!$P$2:$P$2000,"In Progress",'December'!$N$2:$N$2000,"New Prospect") -> 0 | C39: =COUNTIFS('December'!$P$2:$P$2000,"Deal Won",'December'!$N$2:$N$2000,"New Prospect") -> 0 | D39: =COUNTIFS('December'!$P$2:$P$2000,"Deal Lost",'December'!$N$2:$N$2000,"New Prospect") -> 0 | E39: =COUNTIFS('December'!$P$2:$P$2000,"In Progress",'December'!$N$2:$N$2000,"New Prospect") -> 0 | F39: =IF(B39=0,0,C39/B39) -> 0
A40: TOTAL | B40: =SUM(B28:B39) -> 386 | C40: =SUM(C28:C39) -> 107 | D40: =SUM(D28:D39) -> 211 | E40: =SUM(E28:E39) -> 68 | F40: =IF(B40=0,0,C40/B40) -> 0.27720207
B44: DEALS WON BY REGION
B45: Region | C45: Deals Won | D45: % of Won
B46: IN | C46: =COUNTIFS('January'!$P$2:$P$2000,"Deal Won",'January'!$B$2:$B$2000,$B46)+COUNTIFS('February'!$P$2:$P$2000,"Deal Won",'February'!$B$2:$B$2000,$B46)+COUNTIFS('March'!$P$2:$P$2000,"Deal Won",'March'!$B$2:$B$2000,$B46)+COUNTIFS('April'!$P$2:$P$2000,"Deal Won",'April'!$B$2:$B$2000,$B46)+COUNTIFS('May'!$P$2:$P$2000,"Deal Won",'May'!$B$2:$B$2000,$B46)+COUNTIFS('June'!$P$2:$P$2002,"Deal Won",'June'!$B$2:$B$2002,$B46)+COUNTIFS('July'!$P$2:$P$2000,"Deal Won",'July'!$B$2:$B$2000,$B46)+COUNTIFS('August'!$P$2:$P$2000,"Deal Won",'August'!$B$2:$B$2000,$B46)+COUNTIFS('September'!$P$2:$P$2000,"Deal Won",'September'!$B$2:$B$2000,$B46)+COUNTIFS('October'!$P$2:$P$2000,"Deal Won",'October'!$B$2:$B$2000,$B46)+COUNTIFS('November'!$P$2:$P$2000,"Deal Won",'November'!$B$2:$B$2000,$B46)+COUNTIFS('December'!$P$2:$P$2000,"Deal Won",'December'!$B$2:$B$2000,$B46) -> 91 | D46: =IF($F$5=0,0,C46/$F$5) -> 0
B47: US | C47: =COUNTIFS('January'!$P$2:$P$2000,"Deal Won",'January'!$B$2:$B$2000,$B47)+COUNTIFS('February'!$P$2:$P$2000,"Deal Won",'February'!$B$2:$B$2000,$B47)+COUNTIFS('March'!$P$2:$P$2000,"Deal Won",'March'!$B$2:$B$2000,$B47)+COUNTIFS('April'!$P$2:$P$2000,"Deal Won",'April'!$B$2:$B$2000,$B47)+COUNTIFS('May'!$P$2:$P$2000,"Deal Won",'May'!$B$2:$B$2000,$B47)+COUNTIFS('June'!$P$2:$P$2002,"Deal Won",'June'!$B$2:$B$2002,$B47)+COUNTIFS('July'!$P$2:$P$2000,"Deal Won",'July'!$B$2:$B$2000,$B47)+COUNTIFS('August'!$P$2:$P$2000,"Deal Won",'August'!$B$2:$B$2000,$B47)+COUNTIFS('September'!$P$2:$P$2000,"Deal Won",'September'!$B$2:$B$2000,$B47)+COUNTIFS('October'!$P$2:$P$2000,"Deal Won",'October'!$B$2:$B$2000,$B47)+COUNTIFS('November'!$P$2:$P$2000,"Deal Won",'November'!$B$2:$B$2000,$B47)+COUNTIFS('December'!$P$2:$P$2000,"Deal Won",'December'!$B$2:$B$2000,$B47) -> 16 | D47: =IF($F$5=0,0,C47/$F$5) -> 0
B48: EMEA | C48: =COUNTIFS('January'!$P$2:$P$2000,"Deal Won",'January'!$B$2:$B$2000,$B48)+COUNTIFS('February'!$P$2:$P$2000,"Deal Won",'February'!$B$2:$B$2000,$B48)+COUNTIFS('March'!$P$2:$P$2000,"Deal Won",'March'!$B$2:$B$2000,$B48)+COUNTIFS('April'!$P$2:$P$2000,"Deal Won",'April'!$B$2:$B$2000,$B48)+COUNTIFS('May'!$P$2:$P$2000,"Deal Won",'May'!$B$2:$B$2000,$B48)+COUNTIFS('June'!$P$2:$P$2002,"Deal Won",'June'!$B$2:$B$2002,$B48)+COUNTIFS('July'!$P$2:$P$2000,"Deal Won",'July'!$B$2:$B$2000,$B48)+COUNTIFS('August'!$P$2:$P$2000,"Deal Won",'August'!$B$2:$B$2000,$B48)+COUNTIFS('September'!$P$2:$P$2000,"Deal Won",'September'!$B$2:$B$2000,$B48)+COUNTIFS('October'!$P$2:$P$2000,"Deal Won",'October'!$B$2:$B$2000,$B48)+COUNTIFS('November'!$P$2:$P$2000,"Deal Won",'November'!$B$2:$B$2000,$B48)+COUNTIFS('December'!$P$2:$P$2000,"Deal Won",'December'!$B$2:$B$2000,$B48) -> 14 | D48: =IF($F$5=0,0,C48/$F$5) -> 0
B49: EU | C49: =COUNTIFS('January'!$P$2:$P$2000,"Deal Won",'January'!$B$2:$B$2000,$B49)+COUNTIFS('February'!$P$2:$P$2000,"Deal Won",'February'!$B$2:$B$2000,$B49)+COUNTIFS('March'!$P$2:$P$2000,"Deal Won",'March'!$B$2:$B$2000,$B49)+COUNTIFS('April'!$P$2:$P$2000,"Deal Won",'April'!$B$2:$B$2000,$B49)+COUNTIFS('May'!$P$2:$P$2000,"Deal Won",'May'!$B$2:$B$2000,$B49)+COUNTIFS('June'!$P$2:$P$2002,"Deal Won",'June'!$B$2:$B$2002,$B49)+COUNTIFS('July'!$P$2:$P$2000,"Deal Won",'July'!$B$2:$B$2000,$B49)+COUNTIFS('August'!$P$2:$P$2000,"Deal Won",'August'!$B$2:$B$2000,$B49)+COUNTIFS('September'!$P$2:$P$2000,"Deal Won",'September'!$B$2:$B$2000,$B49)+COUNTIFS('October'!$P$2:$P$2000,"Deal Won",'October'!$B$2:$B$2000,$B49)+COUNTIFS('November'!$P$2:$P$2000,"Deal Won",'November'!$B$2:$B$2000,$B49)+COUNTIFS('December'!$P$2:$P$2000,"Deal Won",'December'!$B$2:$B$2000,$B49) -> 7 | D49: =IF($F$5=0,0,C49/$F$5) -> 0
...

Sheet January
A1: Date | B1: Region | C1: Handled by | D1: Email address | E1: Industry | F1: Ticket ID | G1: Purpose | H1: New requirements | I1: Current Platform | J1: Existing data size | K1: Follow up stages | L1: PSE Creation | M1: Source | N1: Engagement Type | O1: Trial sign up | P1: Status | Q1: Deal Size | R1: Revenue | S1: Suggested/purchased edition | T1: Notes | U1: Demo Recording | V1: Sales Notes from CRM | W1: Sprint link
A2: 46024 | B2: IN | C2: Sakthi | D2: umesh.shringi@allen.in | E2: Education | F2: #152989037 | G2: Workplace prospect looking for Trial migration of Google Workspace to WorkDrive and had a few queries on WorkDrive. Helped them complete the test migration. | I2: Google WorkSpace | K2: Do not follow | M2: Internally Looped | N2: New Prospect | O2: POC | P2: Deal Won | Q2: 8000 | R2: 72809.97 | S2: WP flexi | T2: Customer Plan Mail Flexible Plan - 7000 Flexi - Workplace Standard 10gb, 1000 Flexi - Workplace Professional 10gb | V2: No notes
A3: 46024 | B3: IN | C3: Janani | D3: itsupport@kurumgroup.com | E3: Consulting | F3: #149943032 | G3: Prospect is looking for Sign up for Zoho One He already had a session regarding integrating between CRM and WorkDrive and automating features for contacts and creating folders in WorkDrive | H3: Document reminder | I3: System Server | K3: Do not follow | M3: WD support - Chat/Call/Mail | N3: New Prospect | O3: Yes | P3: Deal Won | Q3: 15 | S3: Zoho One | U3: https://workdrive.zoho.in/file/p7iy5e93d0127862f421ebd7bacb82bd32f95 | W3: Document Reminder https://sprints.zoho.in/workspace/zdocs#P15/itemdetails/I7129
A4: 46028 | B4: US | C4: Jennifer | D4: ryan.collins@lsa.inc | E4: Language Service Associates | F4: #153244173 | G4: Currently using Egnyte; facing upload/download action limits with additional costs. Looking for a DMS with no action-based limits, secure file sharing and collection from clients, and smooth collaboration for team members. | I4: Egnyte | J4: < 3 TB | K4: Sales follow up 3 | L4: PSE541721 | M4: WorkDrive - Book a Demo (direct) | N4: New Prospect | O4: No | P4: Deal Lost | Q4: 30 | S4: Team | T4: Price quote is sent in the last mail from the sales team | U4: No recording | V4: Thank you for following up. We do appreciate your time demonstrating your platform and answering any questions we had. Ultimately, we have decided to pursue other vendors that are based in the United States for compliance reasons.
A5: 46028 | B5: IN | C5: Sakthi | D5: mayank.kumar@psb.bank.i | E5: Banking | F5: #153227159 | G5: 1. They were looking for replacement for MS Teams, Outlook, OneDrive and they are currently using WhatsApp for internal communication. >> Suggested Workplace. Gave a quick overview of Workplace. | I5: MS Office 365 | K5: Do not follow | M5: WorkDrive - Book a Demo (direct) | N5: New Prospect | O5: No | P5: Deal Lost | Q5: 1000 | S5: WP flexi
A6: 46028 | B6: IN | C6: Rohith | D6: studio.nkpr@gmail.com | E6: Media | F6: #106824933 | G6: The user had already evaluated WorkDrive in May 2025 and confirmed their decision to proceed. They wanted clarity on the differences between WorkDrive standalone plans and the Workplace bundle. | H6: 1. Custom roles & permission 2. AutoCAD file integration features. | I6: Google personal Drive | K6: Follow up 1 | L6: PSE542077 | M6: From Sales End | N6: New Prospect | O6: Yes | P6: Deal Won | Q6: 7 | S6: WP (Professional) | U6: Connected via direct call | W6: 1. Custom Roles & Permissionshttps://sprints.zoho.in/workspace/zdocs#P15/itemdetails/I7130 2. Auto CAD integration. https://sprints.zoho.in/workspace/zdocs#P15/itemdetails/I7451
A7: 46028 | B7: IN | C7: Rohith | D7: amith@tbkmetalksa.com | E7: Architectural | F7: #152590768 | G7: Demo on Workflows | K7: Sales follow up 2 | L7: PSE542080 | M7: WorkDrive - Book a Demo (direct) | N7: New Prospect | O7: Yes | P7: Deal Won | Q7: 15 | S7: Business | U7: Connected via assist
A8: 46028 | B8: IN | C8: Janani | D8: hareshkapadiya@torrentgas.com | E8: Manufacturing | F8: #153216701 | G8: Prospect is looking for an overview on how to use WorkDrive He have signed up for Trial edition, and wanted to share his screen and know the features on | K8: Sales follow up 3 | M8: From Sales End | N8: New Prospect | O8: Suspended | P8: Deal Lost | Q8: 10 | S8: Starter | U8: https://workdrive.zoho.in/file/wqwyd1273f93c995e4f08a3d4a3143c4e84bd | V8: Ringed and no response over mails/calls
A9: 46028 | B9: IN | C9: Janani | D9: himadri.roy@havrokconsulting.com | E9: Consulting | F9: #153236632 | G9: Prospect is looking for an alternate to Sharepoint in Zoho To store and have a collaboration space | I9: OneDrive | K9: Follow up 1 | M9: WorkDrive - Book a Demo (direct) | N9: New Prospect | O9: Yes | P9: Deal Won | Q9: 1 | S9: Starter | U9: https://workdrive.zoho.in/file/wqwyd0024438bdc594cfe902be9d1abffd67e
A10: 46029 | B10: IN | C10: Sakthi | D10: abhijeet.dey@sedemac.com | E10: Manufacturing | F10: #153282485 | G10: They are currently using PLM application to manager their files internally. | H10: In their existing PLM, they extensively use Major and Minor Version control. >> It is highly crucial for them to have numeric patter link 1.0, 1.1, 1.2,1.3 ….so on and then 2.0, 2.1, 2.2. instead of directly providing 1.0, 2.0, 3.0. >> An option to create minor versions is very critical for their organization. They want an option to manually add minor versions when and where required while checking in a file. Please advise on this feature requirement. | I10: PLM | K10: Sales follow up 3 | M10: WorkDrive - Book a Demo (direct) | N10: New Prospect | O10: No | P10: Deal Lost | Q10: 500 | S10: Business | T10: As we are unable to provide major and minor versioing, we lost this deal. We have also followed up mentioning that we have started working on supporting major and minor versioning. The prospect is yet to get back. | U10: https://workdrive.zoho.in/file/zhubf035eb27aad4042309c8465d67c4437e2 | V10: Sorry for reaching out to you late. After my discussion with the team, we have decided not to go ahead at this time. There are some basic features we require that are currently not present in Zoho WorkDrive. Thank you for your time and for sharing the proposal. | W10: Minor & Major versioning:https://sprints.zoho.in/workspace/zdocs#P15/itemdetails/I7166
A11: 46029 | B11: US | C11: Rohith | D11: cyuhasz@povprint.com | E11: Arts | F11: #153293231 | G11: They need a centralized space to store large files, with the ability to link those files to the corresponding contacts in Zoho CRM. | K11: Do not follow | L11: NO PSE | M11: WorkDrive - Book a Demo (direct) | N11: Existing Paid Cx | O11: Existing user | P11: Existing customer | Q11: 7 | S11: Zoho One | U11: No recording
A12: 46029 | B12: EMEA | C12: Rohith | D12: ry1071220@gmail.com | E12: Education institution | F12: #153303861 | G12: They have a team of fewer than 100 members and need a centralized system to collect individual user information along with related documents. The data includes form-based details and multiple file formats such as Word documents, PDFs, images, and PPTs. Each user should have their own account to upload documents, which must go through a review process. Administrators with appropriate permissions should be able to access, review, and download all submitted files. | H12: None | I12: - | K12: Sales follow up 3 | L12: PSE543061 | M12: From Sales End | N12: New Prospect | O12: Yes | P12: Deal Lost | Q12: 10 to 40 | S12: Business | U12: https://workdrive.zoho.in/file/6ejm19e307182791b490eb753d9252950f3a1 | V12: no response closing mail sent.
A13: 46029 | B13: US | C13: Rohith | D13: dreamloan@centum.ca | E13: Finance | F13: #153320978 | G13: Cloud space to store documents | H13: None | I13: None | K13: Follow up 3 | L13: NO PSE | M13: WorkDrive - Book a Demo (direct) | N13: New Prospect | O13: Yes | P13: Deal Lost | Q13: 4 | T13: No Response from cx | U13: https://workdrive.zoho.in/file/6ejm161f9a100fe264c1895dcfdbd51fb907b
A14: 46029 | B14: IN | C14: Rohith | D14: sukkunmst@gmail.com | E14: Tax | F14: #153338612 | G14: They handle sensitive client tax data and are looking for a secure cloud-based document storage solution. Employees should be able to work on and edit assigned documents, but should not be allowed to download, copy, or externally share those files. | H14: None | I14: Custom roles | K14: Sales follow up 3 | L14: NO PSE | M14: WorkDrive - Book a Demo (direct) | N14: New Prospect | O14: Yes | P14: Deal Lost | Q14: 5 | S14: Starter | U14: No recording | V14: No Response from cx
A15: 46030 | B15: IN | C15: Janani | D15: opagarwalandco@gmail.com | E15: Consulting | F15: #153228475 | G15: Prospect is looking to backup data from system to cloud | H15: None | K15: Sales follow up 1 | M15: From Sales End | N15: New Prospect | O15: Suspended | P15: Deal Lost | Q15: 3 | S15: Starter | U15: https://workdrive.zoho.in/file/ws66nb104dded9b5a4e2dacfa3b077d0a9bd0 | V15: No response
A16: 46030 | B16: IN | C16: Janani | D16: lakshmi@scas.co.in | E16: Consulting | F16: #153274008 | G16: Prospect was looking for cloud storage platform, that helps their clients to login and get access to the files and folders | H16: None | K16: Sales follow up 3 | M16: From Sales End | N16: New Prospect | O16: No | P16: Deal Lost | Q16: 10 | S16: Team | U16: https://workdrive.zoho.in/file/ws66n691a44bcfced4099b76b8ee87659dbf0 | V16: waiting for their management approvals
A17: 46030 | B17: IN | C17: Janani | D17: pankajramol@almamet.com | E17: Logistics | F17: #148152614 | G17: Prospect had demo previously last year wanted to know about the product once again | H17: None | K17: Sales follow up 2 | M17: WD support - Chat/Call/Mail | N17: New Prospect | O17: Yes | P17: Deal Won | Q17: 30 | S17: Team | T17: Deal won in May month | U17: https://workdrive.zoho.in/file/ws66nc4bb16b99a164d7bba22684a0d48aebc
A18: 46030 | B18: IN | C18: Sakthi | D18: finance@tuljaihr.com | E18: Accounting | F18: #153329888 | G18: They are a startup business. They are using LAN to connect their laptops. 2. They want to know if Truesync can be used to sync contents in one laptop to another, where both the laptop belongs to the same user. | K18: Follow up 1 | M18: WorkDrive - Book a Demo (direct) | N18: New Prospect | O18: No | P18: Deal Lost | Q18: 3 | S18: Starter
A19: 46030 | B19: IN | C19: Rohith | D19: dineshk@foodbuddies.in | E19: Food production | F19: #153288747 | G19: They are currently using the Microsoft platform and facing challenges with storage allocation. As a result, they are exploring an alternative solution with better storage flexibility and collaboration capabilities. | H19: None | I19: OneDrive | J19: 1TB | K19: Sales follow up 3 | L19: NO PSE | M19: WorkDrive - Book a Demo (direct) | N19: New Prospect | O19: Free User | P19: Deal Lost | Q19: 4 | S19: Business | U19: Connected via direct call | V19: No Response from cx
A20: 46030 | B20: IN | C20: Rohith | D20: manimaran.g@eduvanta.ai | E20: Education institution | F20: #153090179 | G20: Query in Zoho WorkDrive | H20: None | K20: Do not follow | M20: From Sales End | N20: New Prospect | O20: Yes | P20: Deal Won | Q20: 4 | S20: Starter | U20: https://workdrive.zoho.in/file/f48vvd7cb0f09c40e4251818ceb1060b793ac
A21: 46030 | B21: IN | C21: Rohith | D21: karthik@deducetech.com | E21: Location Content and Maps Industry | F21: #153267281 | G21: They are looking for a cloud storage solution to support daily data transfers from Mexico to India. The expected upload volume is around 600–800 GB per day. The data will be downloaded to their NAS at the Bangalore location and then deleted from the cloud, so the requirement is primarily for high-volume, short-term data transfer with reliability and performance. | H21: None | I21: OneDrive | J21: 2TB | K21: Sales follow up 3 | L21: NO PSE | M21: WD support - Chat/Call/Mail | N21: New Prospect | O21: Suspended | P21: Deal Lost | S21: Business | U21: https://workdrive.zoho.in/file/f48vv5fb9145b6e0a46eba97dfa74f321bb1b | V21: No Response from cx
A22: 46030 | B22: US | C22: Rohith | D22: info@tangoshieldsecurity.com | E22: IT security | F22: #153360663 | G22: They are an MSP supporting a global distribution client, they are looking for a WorkDrive-focused demo covering strong admin-level control and security policies for BYOD users, integration with Zoho One and third-party systems such as ERP and WMS, encrypted file sharing with detailed audit trails for compliance, geo-restricted access and DLP use cases, and scalable storage with reliable multi-region performance. They also requested examples aligned with high-volume document management and regulated environments such as FedRAMP, HIPAA, and GDPR. | H22: None | K22: Sales follow up 3 | L22: NO PSE | M22: WorkDrive - Book a Demo (direct) | N22: New Prospect | O22: Suspended | P22: Deal Lost | Q22: 10 | S22: Business | U22: https://workdrive.zoho.in/file/6ejm18c85937609b349a0bd9fa53826adc669 | V22: No Response from cx
A23: 46031 | B23: IN | C23: Sakthi | D23: systemengineer@niperhajipur.ac.in | E23: Government sector | F23: #153348227 | G23: 1. Their primary requirement is to have a Workflow set up for the below mentioned use-case: >> They want to trigger a workflow of approval for their purchase orders and other kinds of documents from: Administrative Officer-> Registrar-> Dean-> Sometimes to HOD for inputs-> Director | K23: Follow up 1 | M23: WorkDrive - Book a Demo (direct) | N23: New Prospect | O23: No | P23: Deal Lost | Q23: 50 | S23: Business | U23: https://workdrive.zoho.in/file/x4582ce625fce28734c4d9388e7f5e3e02e4b
A24: 46031 | B24: IN | C24: Sakthi | D24: milin.patel@kokuyocamlin.com | E24: Manufacturing | F24: #153385675 | G24: Looking for features like DLP, Access control and team folder based collaboration | H24: Logs for Print actions in org-level activity report. | K24: Sales follow up 2 | M24: WD support - Chat/Call/Mail | N24: New Prospect | O24: Suspended | P24: Deal Lost | Q24: 12 | S24: Business | U24: https://workdrive.zoho.in/file/l4d7771c8b8a0ee8b4c07b59c6700fbe0ccbc | W24: Print logs in activity report: https://sprints.zoho.in/workspace/zdocs#P15/itemdetails/I7459
A25: 46031 | B25: IN | C25: Janani | D25: katearf@hotmail.com | E25: Consulting | F25: #153382549 | G25: Prospect is looking for an alternate to DropBox And primary requirement is to share and collaborate with external users | K25: Sales follow up 3 | M25: WorkDrive - Book a Demo (direct) | N25: New Prospect | O25: No | P25: Deal Lost | Q25: 46298 | S25: Starter | U25: https://workdrive.zoho.in/file/l4d77cdc4bc7e500b42bba65e3e67c24e05ea
A26: 46031 | B26: IN | C26: Janani | D26: mrunalini.hr@mecpl.in | E26: construction | F26: #153385925 | G26: Primary requirement is to replace Google Sheet in Zoho Since sales team suggested it is not possible to collaborate only with Zoho Sheet sign up, | K26: Sales follow up 2 | M26: From Sales End | N26: New Prospect | O26: Yes | P26: Deal Won | Q26: 380 | R26: 4965.84 | S26: Starter | U26: https://workdrive.zoho.in/file/l4d77f7b0389ece7a4be3a0c7a3a462c09d3c
A27: 46031 | B27: IN | C27: Janani | D27: md.arif@imoneypay.in | E27: financial services | F27: #153322758 | G27: Prospect is looking for Zoho apps in common as they are Indian made and mainly a DLP solution | H27: - DLP feature, whether it is available as standalone in Zoho same an microsfot purvie | K27: Follow up 3 | M27: WD support - Chat/Call/Mail | N27: New Prospect | O27: No | P27: Deal Lost | Q27: Not confirmed | S27: Starter | U27: https://workdrive.zoho.in/file/ws66n64d3e72d3dd14e6bbeba404ea19e48d1
A28: 46031 | B28: IN | C28: Janani | D28: hemstoneomondi5@gmail.com | E28: Consulting | F28: #153349646 | G28: Prospect has already signed up for Trial edition and wanted to explore all the features in Zoho WorkDrive | K28: Sales follow up 3 | M28: WorkDrive - Book a Demo (direct) | N28: New Prospect | O28: Yes | P28: Deal Lost | Q28: 46176 | S28: Zoho One | T28: Zoho One lead | U28: https://workdrive.zoho.in/file/ws66n48004e8458ff438696f2365cc533f55b
A29: 46031 | B29: IN | C29: Janani | D29: prashant.kumar@omnioffshore.com | E29: marine & offshore oil services | F29: #102351238 | G29: Prospect is looking for an We are looking for an online document management system for our project team. Almost all project documents are in pdf format. The solution should be able to handle commenting and review of pdf documents. | H29: - He wanted to see if we can have comment export feature - Export the document workflow status on track workflow page So that they can have reports of all the file that has been gone through reviewal and approval process OR On every approval and reviewal process, is it possible to add a stamp once the review or approval gets completed | K29: Sales follow up 3 | M29: From Sales End | N29: New Prospect | O29: Suspended | P29: Deal Lost | Q29: 15 | S29: Business | U29: https://workdrive.zoho.in/file/ws66ned19fb2bc802423c8fcbd6d1a77af93b | V29: The team is actively testing the system now using a trial account. We should have an outcome in a few days., I am sorry to inform that the final decision was not in your favour. I really wanted to move to Zoho WorkDrive but could not convince the engineering team.
A30: 46031 | B30: IN | C30: Rohith | D30: nidhi@gepathways.com.au | E30: Overseas education | F30: #151471225 | G30: They have a distributed team working from multiple locations and need a centralized document repository. Currently, files are stored on individual machines, which has resulted in duplication, version confusion, and difficulty collaborating across teams. | H30: None | I30: Local Drive | K30: Follow up 2 | L30: PSE543164 | M30: From Sales End | N30: New Prospect | O30: Yes | P30: Deal Won | Q30: 13 | S30: Business | U30: https://workdrive.zoho.in/file/l4d7742e2fd04bdaf4e4793aa54788af17d08
A31: 46031 | B31: IN | C31: Sakthi | D31: trs@zengroupindia.com | E31: Manufacturing | F31: #153385675 | G31: 1. They were currently using hard-disk to manage their files. Accessibility was their primary concern. 2. They have requested for Workflow feature where they want to send document to multiple approvers. | K31: Follow up 1 | M31: WD support - Chat/Call/Mail | N31: New Prospect | O31: Yes | P31: Deal Won | Q31: 11 | R31: 402.93 | S31: Team | U31: https://workdrive.zoho.in/file/l4d77229e30639a8c4f628b69b68db7826a5d
A32: 46031 | B32: IN | C32: Rohith | D32: advbhagat@zohomail.in | E32: Personal use | F32: #153404681 | G32: Queries on Zoho Writer and WorkDrive | I32: Google Drive | K32: Sales follow up 3 | L32: NO PSE | M32: WD support - Chat/Call/Mail | N32: New Prospect | O32: No | P32: Deal Lost | U32: No recording | V32: No Response from cx
A33: 46031 | B33: IN | C33: Rohith | D33: premchand4892@gmail.com | E33: Consultant | F33: #153030903 | G33: They are looking for a spreadsheet tool to manage client details such as name, email, and other information. | H33: While locking the cell, copy action should be restricted | I33: None | K33: Follow up 3 | L33: NO PSE | M33: WorkDrive - Book a Demo (direct) | N33: New Prospect | O33: No | P33: Deal Lost | Q33: 2 | S33: Starter | T33: No Response from cx | U33: No recording
A34: 46031 | B34: IN | C34: Jennifer | D34: manickavalli@gmail.com | E34: Unknown | F34: #153385007 | G34: They are using Google Drive and OneDrive to manage their documents from desktop version, however they have challenges with simultaneous syncing process. Plus they are looking to maintain their private files separately and have desktop app that does not take up the system storage. | I34: Google Drive and OneDrive | J34: ~200 GB | K34: Sales follow up 1 | L34: PSE543282 | M34: WD support - Chat/Call/Mail | N34: New Prospect | O34: Yes | P34: Deal Won | Q34: 3 | S34: Starter | U34: https://workdrive.zoho.in/file/kdqtxe1f50aa9bb484e7e945d487af9fa6616
A35: 46034 | B35: IN | C35: Janani | D35: contact@theanant.in | E35: Consulting | F35: #153333592 | G35: Work Drive, WorkSpace, Biomatric & Attendance, Work Space - App | K35: Sales follow up 1 | M35: From Sales End | N35: New Prospect | O35: No | P35: Deal Lost | Q35: 15 | S35: WP (Standard) | U35: https://workdrive.zoho.in/file/x3dyzcd408f3ba3cb4bca9e33b7185d830bf4
A36: 46034 | B36: IN | C36: Janani | D36: kesar240391@gmail.com | E36: Personal | F36: #153445929 | G36: Prospect is looking for an overview on WorkDrive and the features | K36: Sales follow up 2 | M36: WorkDrive - Book a Demo (direct) | N36: New Prospect | O36: No | P36: Deal Lost | Q36: 10 | S36: Starter | U36: https://workdrive.zoho.in/file/x3dyz7ce9c57c565942d6be20aabbf0fb4f54
A37: 46034 | B37: IN | C37: Rohith | D37: wlfoundation@outlook.com | E37: NGO | F37: #153394548 | G37: They are looking for a centralized cloud storage solution to manage data across all project locations, with real-time access for the Hyderabad head office as files are uploaded. They also require controlled folder access per project/location, detailed activity tracking (uploads, edits, moves, and sharing), and an affordable pricing model, preferably with NGO-specific discounts | H37: None | I37: DY box | K37: Sales follow up 2 | L37: NO PSE | M37: WorkDrive - Book a Demo (direct) | N37: New Prospect | O37: Yes | P37: Deal Won | Q37: 4 | S37: Starter | U37: https://workdrive.zoho.in/file/k5iz65300f78e357e4ed2af76077fab7957a4
A38: 46034 | B38: IN | C38: Rohith | D38: amith@tbkmetalksa.com | E38: Architectural | F38: #152590768 | G38: Queries in Zoho WorkDrive | K38: Sales follow up 2 | L38: PSE543884 | M38: WorkDrive - Book a Demo (direct) | N38: Already Engaged Px | O38: Yes | P38: Deal Won | Q38: 15 | R38: 1034.5 | S38: Business | U38: Connected via assist
A39: 46034 | B39: EMEA | C39: Rohith | D39: mohammed.wedaa@alqasabi.sa | E39: Constructions | F39: #152978135 | G39: The customer is looking for a centralized document management system to manage all project-related files with controlled access at both folder and subfolder levels. They need clearly defined review and approval workflows involving contractors, consultants, and clients, along with strong version control and complete audit trails. Approved documents should be locked to prevent further edits, and they require document logs (such as drawing registers) to track approvals and document history. Additionally, they need powerful search capabilities to manage large volumes of files and scalable storage that can be expanded as the project grows. | H39: None | I39: None | K39: Sales follow up 2 | L39: PSE543890 | M39: WorkDrive - Book a Demo (direct) | N39: New Prospect | O39: Suspended | P39: Deal Lost | Q39: 30 | S39: Business | U39: https://workdrive.zoho.in/file/k5iz639d8b63eb02e4db7beefe4945ab0b613 | V39: Sales followed up in mail
A40: 46034 | B40: IN | C40: Rohith | D40: nagesh.dhumma@dhummaconsulting.com | E40: Consulting Services | F40: #152928511 | G40: They are looking for a combined project and document management solution. Their key needs include centralized document storage with controlled access to files, clear visibility into team progress, and the ability to collaborate seamlessly with team members in Germany. They also require easy access to files and updates from both desktop and mobile devices. | H40: None | I40: Trello | J40: 1.5TB | K40: Follow up 2 | L40: PSE543898 | M40: WorkDrive - Book a Demo (direct) | N40: New Prospect | O40: Yes | P40: Deal Won | Q40: 5 | S40: Team | U40: https://workdrive.zoho.in/file/k5iz6d47bfeadc843479cb9f6a6ef4c7b9688
...

Sheet February
A1: Date | B1: Region | C1: Handled by | D1: Email address | E1: Industry | F1: Ticket ID | G1: Purpose | H1: New requirements | I1: Current Platform | J1: Existing data size | K1: Follow up stages | L1: PSE Creation | M1: Source | N1: Engagement Type | O1: Trial sign up | P1: Status | Q1: Deal Size | R1: Revenue | S1: Suggested/purchased edition | T1: Notes | U1: Demo Recording | V1: Sales Notes from CRM | W1: Sprint link
A2: 46055 | B2: IN | C2: Sakthi | D2: shinoy.thachapully@ae.mcd.com | E2: Food | F2: #154488423 | G2: They are currently using Legacy NTFS Windows server and they want to migrate over to Zoho WorkDrive. | H2: They have requested for UAE sensitive information types like Emirates passport, Emirates ID. >> We have requested for the list of predefined sensitive information types that need to be added by default. They want exemptions for files applied with DLP. Like a time based exemption. >> As of now, marking “Remove classification label”, once marked it is not time based exemptions. >> Once the time is set up the want the removed classification label to be reapplied with the classification label. They have requested for integration with Teams, Office 365, Sharepoint. >> Do we have any integration with Teams in our roadmap. For O365 we can suggest MS office extension. For Sharepoint, we have requested for more information. | I2: Legacy NTFS Windows server | K2: Sales follow up 3 | M2: WorkDrive - Book a Demo (direct) | N2: New Prospect | O2: No | P2: Deal Lost | Q2: 550 | S2: Business | U2: MS Teams | V2: Update from Shinoy - Mc D "I am in talk with our global cyber team to whitelist Zoho workdrive for POC" | W2: 1. UAE Sensitive information type:https://sprints.zoho.in/workspace/zdocs#P15/itemdetails/I7229 2. ZScalar integration: https://sprints.zoho.in/workspace/zdocs#P15/itemdetails/I7231
A3: 46055 | B3: IN | C3: Janani | D3: info@prcas.com | E3: Financial | F3: #154380360 | G3: Zoho Mail user, need more information on Individual edition as of now they are looking to store data to Zoho WorkDrive cloud | J3: GDrive | K3: Follow up 1 | M3: WorkDrive - Book a Demo (direct) | N3: New Prospect | O3: Yes | P3: Deal Won | Q3: 1 | S3: WP (Standard) | U3: https://workdrive.zoho.in/file/1obh949b6c61eb6a84224837ee046365ba7f4
A4: 46055 | B4: US | C4: Rohith | D4: adam.teitelbaum@wartsila.com | E4: Sales | F4: #154399628 | G4: They are looking to build a centralized sales content library where all documents are stored in one place and can be easily searched and filtered based on content types. The setup should allow a single admin to create, edit, and manage all sales content, while the sales team should have view-only access to ensure content consistency. Additionally, they are looking for a cost-effective licensing model to support this structure. | H4: None | I4: Local Drive | K4: Sales follow up 3 | L4: No PSE | M4: WorkDrive - Book a Demo (direct) | N4: New Prospect | O4: Yes | P4: Deal Lost | Q4: 3 + 20CL | S4: Business | U4: https://workdrive.zoho.in/file/ddt54977a91741ab644a7a34ed16fdd888522 | V4: No response from cx
A5: 46055 | B5: US | C5: Jennifer | D5: atkconsult3@gmail.com | E5: Financial Services | F5: #154433327 | G5: They are exploring broader Zoho apps and planning to move to the zoho ecosystem and have signed up for Zoho One already. Concerning WD, they are looking for multiple user access, with permissions applied for now. | H5: 7-year data retention feasibility | K5: Z1 follow up | L5: No PSE | M5: WorkDrive - Book a Demo (direct) | N5: New Prospect | O5: Yes | P5: Deal Lost | Q5: 1 | S5: Zoho One | T5: Still in trial evaluating - Zoho one | U5: https://workdrive.zoho.in/file/f19a64b5d1cc9053747c28108e2dac2ef2202 | W5: https://sprints.zoho.in/workspace/zdocs#P15/itemdetails/I6334/details
A6: 46056 | B6: US | C6: Jennifer | D6: jasonb@ricelandcabinet.com | E6: Manufacturing | F6: #153778548 | G6: They currently need their team members to be able to capture pictures from their different branches to WorkDrive, where their staff members are not tech savvy. They are also looking for document sharing with their clients, which they have been doing with zoho mail now. they also used dropbox, but not extensively, so no comments on it. | H6: None | K6: Sales follow up 3 | L6: PSE550740 | M6: From Sales End | N6: New Prospect | O6: Suspended | P6: Deal Lost | Q6: 20 | S6: Starter | U6: https://workdrive.zoho.in/file/f19a68b15f4e7792d4555abacf49e9747e5fa | V6: second follow up mail sent
A7: 46056 | B7: IN | C7: Jennifer | D7: jay19shah@gmail.com | E7: Financial Services | F7: #154475521 | G7: They have been using local server, NAS backup for all these years, however they have been having challenges with accessing and planning to move to a cloud based to maintain their files with MS office, PDF, Image extensions. They currently own 100 GB of data and expecting to expand a little more, with the options to access from mobile and set access levels for their members. | H7: None | I7: Local Server | J7: 100 GB | K7: Sales follow up 3 | L7: PSE551193 | M7: From Sales End | N7: New Prospect | O7: Suspended | P7: Deal Lost | Q7: 10 | S7: Starter | U7: https://workdrive.zoho.in/file/ddt54b473e77fb44945c293458b101e058863 | V7: no response from the prospect
A8: 46056 | B8: IN | C8: Janani | D8: atchula@zohomail.in | E8: Personal | F8: #154485655 | G8: Prospect needs cloud storage to store family photos | J8: Google photos | K8: Sales follow up 3 | M8: WD support - Chat/Call/Mail | N8: New Prospect | O8: Yes | P8: Deal Lost | Q8: 1 | S8: Free Individual | U8: https://workdrive.zoho.in/file/1obh926832b4cfd46447da8bc10c8696c80f3
A9: 46056 | B9: IN | C9: Janani | D9: edp@krishcarbon.com | E9: Manufacturing | F9: #154465180 | G9: Prospect is looking for our primary requirement is that we want to share the document within our organisation. | J9: System server | K9: Sales follow up 3 | M9: From Sales End | N9: New Prospect | O9: Yes | P9: Deal Lost | Q9: 10-15 | S9: Team | U9: https://workdrive.zoho.in/file/1obh994e2751b212f4d9aadb75e58ef3b08b3 | V9: Spoke with cx and they are not looking for this application currently.
A10: 46056 | B10: IN | C10: Janani | D10: anas@goldenfinty.com | E10: Electrical & Mechanical Contracting | F10: #154413902 | G10: Prospect is looking for an cloud storage platform where they collect data and store in cloud for other team members to access it | J10: OneDrive | K10: Sales follow up 3 | M10: WorkDrive - Book a Demo (direct) | N10: New Prospect | O10: No | P10: Deal Lost | Q10: 10 | S10: Starter | U10: https://workdrive.zoho.in/file/1obh945e5f09f915347f8b718ae51057b3684
A11: 46056 | B11: IN | C11: Janani | D11: sumit@nagpal.law | E11: Law | F11: #150564803 | G11: Prospect is using OneDrive and wanted to switch to zoho due to some challenges in OneDrive | J11: OneDrive | K11: Sales follow up 2 | M11: WorkDrive - Book a Demo (direct) | N11: New Prospect | O11: No | P11: Deal Lost | Q11: 13 | S11: Starter | U11: https://workdrive.zoho.in/file/1obh9b436450577644980959b6c12196cae41 | V11: Looking for Zoho Workplace
A12: 46056 | B12: IN | C12: Rohith | D12: raghav.banflexcables@gmail.com | E12: B2B | F12: #154464648 | G12: They are a B2B cable company based in Delhi currently using a local network drive, which lacks proper access control, leads to version conflicts, and makes it difficult to access data outside the office. | H12: None | I12: Network Drive | J12: 5GB | K12: Sales follow up 3 | L12: PSE551368 | M12: From Sales End | N12: New Prospect | O12: Yes | P12: Deal Lost | Q12: 46366 | S12: Team | U12: https://workdrive.zoho.in/file/r9vht2a9685e2dd3b425e8b317fd51a72891c | V12: Px declined the call after introduction
A13: 46056 | B13: IN | C13: Rohith | D13: nistha@caankur.com | E13: IT | F13: #154475061 | G13: They are looking for a document storage solution to manage client data, where users can edit files but are restricted from deleting them unless the admin explicitly allows it. At present, all documents are stored on a local drive. They have evaluated other tools but felt those solutions did not adequately address their access control and permission requirements. | H13: None | I13: Local Drive | K13: Sales follow up 3 | L13: PSE551387 | M13: WorkDrive - Book a Demo (direct) | N13: New Prospect | O13: Yes | P13: Deal Lost | U13: https://workdrive.zoho.in/file/ddt54852a6401347e4589aa9fca6f858d7e35 | V13: spoke with px she stated that they will continue with their existing subscription
